Workbook
Name Càn: '64Quẻ'!$B$6:$B$11
Name Đ.Nhân: '64Quẻ'!$F$6:$F$11
Name Lý: '64Quẻ'!$D$6:$D$11

Sheet Giới thiệu
B2: Đây là chương trình lập số mệnh và xem vận theo phương pháp Hà Lạc Lý Số, dựa trên cuốn "Bát Tự Hà Lạc số" của Học Năng.
B3: Với khoảng : 384 X (5 + 3 + 2) + 34 = 3874 Cách cục khác nhau. (Nếu tính chi li tổng số âm dương... thì còn nhiều nữa)
B4: (Trong đó : 384 = 64 quẻ X 6 hào. 5/10 thể cách. 3 là Thiên địa nguyên khí hóa công. 2 là nạp giáp và tháng sinh. 34 cách quý hiển)
B6: Chương trình hoàn toàn được viết bằng hàm Excel, không sử dụng Macro. Riêng hàm đổi Dương lịch sang Âm lịch là sưu tầm của một tác giả không biết tên. Phần tiết khí theo tác giả Hồ Ngọc Đức.
B9: Chương trình chỉ dùng cho người được sinh ra ở Hà Nội và khu vực lân cận cùng kinh độ vì lịch tiết khí ứng dụng trong chương trình chỉ tính cho khu vực này. Chương trình chỉ lập được số cho người sinh ra trong khoảng thời gian từ 1-1-1990 đến 31-12-2043, vì phần lịch tiết khí chỉ cập nhật trong khoảng đó. Lịch của chương trình tương tác với cài đặt thời gian trong máy tính này !
B13: Nếu có một ngày tháng nào đó âm lịch là tháng 1 mà chi tháng trong tứ trụ lại là tháng Sửu hoặc Mão,… thì bạn đừng vội bảo nó sai vì môn này tính Can chi tháng theo Tiết khí (Vào tiết "Lập xuân" là bước vào tháng giêng, nguyệt kiến Dần,… Năm cũng vậy, vào Lập xuân mới tính năm Can chi khác). Cũng nên lưu ý giờ phút vào tiết : Đến thời khắc đó mới vào tiết - tức bước vào tháng mới !
B17: Lưu trữ ngày sinh của nhiều người và xem được cho những người đó mà không phải nhập lại ngày sinh - Chỉ trên một file này !
B19: Kinh nghiệm : Nếu bạn sinh vào đầu hoặc cuối của một giờ can chi hoặc gần lúc vào tiết thì bạn nên lập thêm một lá số nữa vào giờ can chi trước hoặc sau, hoặc trước sau thời điểm giao tiết để chiêm nghiệm các sự kiện đã diễn ra trong quá khứ, lá số nào đúng thì giờ đó đúng.
B23: Viết tắt : MHC, MKH =Mệnh hợp cách, mệnh không hợp; QC, GS, NT = Quan chức, Giới sĩ, Người thường; TNK, ĐNK, HC : Thiên địa nguyên khí hóa công.
B25: Lúc ở công sở thì xem mục "QC", khi học hành thi thố thì xem mục "GS", còn lại thì mọi người đều nên xem mục "NT".
L27: letrungtu2008@yahoo.com
B28: " Kinh dịch là đạo của người quân tử "
B30: " Kinh dịch quý nhất chữ thời " (Nguyễn Bỉnh Khiêm)
L32: " Thuận thời thì sống, nghịch thời thì chết "

Sheet Nhập liệu
B1: Bảng nhập dữ liệu | L1: Không sử dụng Cut & Paste.
L2: Dùng Unicode để gõ có dấu. Chỉ gõ vào cột có chữ mầu xanh.
B3: TT | C3: Họ & tên | D3: Nam | E3: Dương lịch | H3: Giờ | I3: Phút | J3: Ghi chú | K3: Kiểm tra
D4: Nữ | E4: Ngày | F4: Tháng | G4: Năm | H4: 0-23 | I4: 0-59 | J4: Ngày giờ sinh
B5: 1 | C5: Lá số | D5: Nữ | E5: 17 | F5: 2 | G5: 2002 | H5: 7 | I5: 0 | K5: =IF(D5="","",D5) -> Nữ | L5: =IF(H5="","",DATE(G5,F5,E5)+TIME(H5,I5,0)) -> 37304.292
B6: 2 | K6: =IF(D6="","",D6) | L6: =IF(H6="","",DATE(G6,F6,E6)+TIME(H6,I6,0))
B7: 3 | K7: =IF(D7="","",D7) | L7: =IF(H7="","",DATE(G7,F7,E7)+TIME(H7,I7,0))
B8: 4 | K8: =IF(D8="","",D8) | L8: =IF(H8="","",DATE(G8,F8,E8)+TIME(H8,I8,0))
B9: 5 | K9: =IF(D9="","",D9) | L9: =IF(H9="","",DATE(G9,F9,E9)+TIME(H9,I9,0))
B10: 6 | K10: =IF(D10="","",D10) | L10: =IF(H10="","",DATE(G10,F10,E10)+TIME(H10,I10,0))
B11: 7 | K11: =IF(D11="","",D11) | L11: =IF(H11="","",DATE(G11,F11,E11)+TIME(H11,I11,0))
B12: 8 | K12: =IF(D12="","",D12) | L12: =IF(H12="","",DATE(G12,F12,E12)+TIME(H12,I12,0))
B13: 9 | K13: =IF(D13="","",D13) | L13: =IF(H13="","",DATE(G13,F13,E13)+TIME(H13,I13,0))
B14: 10 | K14: =IF(D14="","",D14) | L14: =IF(H14="","",DATE(G14,F14,E14)+TIME(H14,I14,0))
B15: 11 | K15: =IF(D15="","",D15) | L15: =IF(H15="","",DATE(G15,F15,E15)+TIME(H15,I15,0))
B16: 12 | K16: =IF(D16="","",D16) | L16: =IF(H16="","",DATE(G16,F16,E16)+TIME(H16,I16,0))
B17: 13 | K17: =IF(D17="","",D17) | L17: =IF(H17="","",DATE(G17,F17,E17)+TIME(H17,I17,0))
... B104: 100 | K104: =IF(D104="","",D104) | L104: =IF(H104="","",DATE(G104,F104,E104)+TIME(H104,I104,0))
K105: =IF(D105="","",D105) | L105: =IF(H105="","",DATE(G105,F105,E105)+TIME(H105,I105,0))
L1001: =IF(H1001="","",DATE(G1001,F1001,E1001)+TIME(H1001,I1001,0))
L1002: =IF(H1002="","",DATE(G1002,F1002,E1002)+TIME(H1002,I1002,0))
L1003: =IF(H1003="","",DATE(G1003,F1003,E1003)+TIME(H1003,I1003,0))
L1004: =IF(H1004="","",DATE(G1004,F1004,E1004)+TIME(H1004,I1004,0))

Sheet Thể cách
B1: BÁT TỰ HÀ LẠC SỐ
AP2: =IF('Nhập liệu'!C5="","",'Nhập liệu'!C5) -> Lá số
D3: Lá số | I3: =Setup!G19 -> (+) Nữ | M3: Quẻ tiên thiên | Q3: Quẻ hậu thiên | AP3: =IF('Nhập liệu'!C6="","",'Nhập liệu'!C6)
F4: =IF(D3="","Máy tự động lập số Nam giới giờ này",IF(ISNA(VLOOKUP(D3,'Nhập liệu'!C5:L1004,10,0)),"Máy tự động lập số Nam giới giờ này","giờ "&INDEX(Setup!E8:E19,MOD(Setup!BY9/2+1/2,12)+1)&" "&Setup!BY17&"/"&Setup!BY18&" "&Setup!BZ19&" "&Setup!CA19)) -> giờ Thìn 6/1 Nhâm Ngọ | L4: =IF(Setup!AA40=6,"NĐ","") | M4: =HLOOKUP(M10,'64Quẻ'!B5:DX11,2,0) -> ——— | N4: =Setup!M23&"-"&Setup!N23 -> 10-18 | O4: =HLOOKUP(M10&1,'64Quẻ'!B5:DY11,2,0) -> N.Tuất | P4: =IF(Setup!AA40=3,"NĐ","") | Q4: =HLOOKUP(Q10,'64Quẻ'!B5:DX11,2,0) -> — — | R4: =Setup!O23&"-"&Setup!P23 -> 73-78 | S4: =HLOOKUP(Q10&1,'64Quẻ'!B5:DY11,2,0) -> Q.Dậu | AP4: =IF('Nhập liệu'!C7="","",'Nhập liệu'!C7)
B5: =Setup!B9 -> 37291.308 | E5: =IF(D3="",NOW(),IF(ISNA(VLOOKUP(D3,'Nhập liệu'!C5:L1004,10,0)),"Vừa đổi tên người này",VLOOKUP(D3,'Nhập liệu'!C5:L1004,10,0))) -> 37304.292 | H5: =VLOOKUP(Setup!B17,TiếtKhí!B3:D3626,3,0) -> 37321.061 | L5: =IF(Setup!AA40=5,"NĐ","") -> NĐ | M5: =HLOOKUP(M10,'64Quẻ'!B5:DX11,3,0) -> ——— | N5: =Setup!M24&"-"&Setup!N24 -> 1-9 | O5: =HLOOKUP(M10&1,'64Quẻ'!B5:DY11,3,0) -> N.Thân | P5: =IF(Setup!AA40=2,"NĐ","") | Q5: =HLOOKUP(Q10,'64Quẻ'!B5:DX11,3,0) -> — — | R5: =Setup!O24&"-"&Setup!P24 -> 67-72 | S5: =HLOOKUP(Q10&1,'64Quẻ'!B5:DY11,3,0) -> Q.Hợi | AP5: =IF('Nhập liệu'!C8="","",'Nhập liệu'!C8)
C6: =IF(Setup!B14=1,VLOOKUP(Setup!B16,TiếtKhí!B3:D3626,2,0)&" :",VLOOKUP(Setup!B16,TiếtKhí!B3:D3626,2,0)) -> Lập xuân | F6: =">> "&IF(Setup!B14=1,"Tiết lệnh tháng 12","Tiết lệnh tháng "&Setup!B14-1)&" >>" -> >> Tiết lệnh tháng 1 >> | I6: =VLOOKUP(Setup!B17,TiếtKhí!B3:D3626,2,0) -> Kinh trập | L6: =IF(Setup!AA40=4,"NĐ","") | M6: =HLOOKUP(M10,'64Quẻ'!B5:DX11,4,0) -> ——— | N6: =Setup!M25&"-"&Setup!N25 -> 37-45 | O6: =HLOOKUP(M10&1,'64Quẻ'!B5:DY11,4,0) -> N.Ngọ | P6: =IF(Setup!AA40=1,"NĐ","") | Q6: =HLOOKUP(Q10,'64Quẻ'!B5:DX11,4,0) -> — — | R6: =Setup!O25&"-"&Setup!P25 -> 61-66 | S6: =HLOOKUP(Q10&1,'64Quẻ'!B5:DY11,4,0) -> Q.Sửu | AP6: =IF('Nhập liệu'!C9="","",'Nhập liệu'!C9)
E7: Năm : | F7: =Setup!S6&" "&Setup!T6 -> Nhâm Ngọ | L7: =IF(Setup!AA40=3,"NĐ","") | M7: =HLOOKUP(M10,'64Quẻ'!B5:DX11,5,0) -> — — | N7: =Setup!M26&"-"&Setup!N26 -> 31-36 | O7: =HLOOKUP(M10&1,'64Quẻ'!B5:DY11,5,0) -> Ấ.Mão | P7: =IF(Setup!AA40=6,"NĐ","") | Q7: =HLOOKUP(Q10,'64Quẻ'!B5:DX11,5,0) -> ——— | R7: =Setup!O26&"-"&Setup!P26 -> 52-60 | S7: =HLOOKUP(Q10&1,'64Quẻ'!B5:DY11,5,0) -> K.Hợi | AP7: =IF('Nhập liệu'!C10="","",'Nhập liệu'!C10)
E8: Tháng : | F8: =Setup!S7&" "&Setup!T7 -> Nhâm Dần | I8: ="Tổng số Dg : "&Setup!H23 -> Tổng số Dg : 20 | L8: =IF(Setup!AA40=2,"NĐ","") | M8: =HLOOKUP(M10,'64Quẻ'!B5:DX11,6,0) -> — — | N8: =Setup!M27&"-"&Setup!N27 -> 25-30 | O8: =HLOOKUP(M10&1,'64Quẻ'!B5:DY11,6,0) -> Ấ.Tỵ | P8: =IF(Setup!AA40=5,"NĐ","") -> NĐ | Q8: =HLOOKUP(Q10,'64Quẻ'!B5:DX11,6,0) -> — — | R8: =Setup!O27&"-"&Setup!P27 -> 46-51 | S8: =HLOOKUP(Q10&1,'64Quẻ'!B5:DY11,6,0) -> K.Sửu | AP8: =IF('Nhập liệu'!C11="","",'Nhập liệu'!C11)
E9: Ngày : | F9: =Setup!S8&" "&Setup!T8 -> Bính Thìn | I9: ="Tổng số Âm : "&Setup!I23 -> Tổng số Âm : 56 | L9: =IF(Setup!AA40=1,"NĐ","") | M9: =HLOOKUP(M10,'64Quẻ'!B5:DX11,7,0) -> — — | N9: =Setup!M28&"-"&Setup!N28 -> 19-24 | O9: =HLOOKUP(M10&1,'64Quẻ'!B5:DY11,7,0) -> Ấ.Mùi | P9: =IF(Setup!AA40=4,"NĐ","") | Q9: =HLOOKUP(Q10,'64Quẻ'!B5:DX11,7,0) -> ——— | R9: =Setup!O28&"-"&Setup!P28 -> 79-87 | S9: =HLOOKUP(Q10&1,'64Quẻ'!B5:DY11,7,0) -> K.Mão | AP9: =IF('Nhập liệu'!C12="","",'Nhập liệu'!C12)
E10: Giờ : | F10: =Setup!S9&" "&Setup!T9 -> Nhâm Thìn | M10: =Setup!I27 -> Bĩ | Q10: =HLOOKUP(Setup!L22,'64Quẻ'!B4:DX5,2,0) -> M.Di | AP10: =IF('Nhập liệu'!C13="","",'Nhập liệu'!C13)
M11: ="Tháng : "&HLOOKUP(M10,'64Quẻ'!B5:DX25,21,0) -> Tháng : 7 | Q11: ="Tháng : "&HLOOKUP(Q10,'64Quẻ'!B5:DX25,21,0) -> Tháng : 8 | AP11: =IF('Nhập liệu'!C14="","",'Nhập liệu'!C14)
T12: Nhấp chuột vào ô họ tên mầu vàng để xem thể cách người khác trong bảng nhập liệu | AP12: =IF('Nhập liệu'!C15="","",'Nhập liệu'!C15)
B13: Thể cách : | AP13: =IF('Nhập liệu'!C16="","",'Nhập liệu'!C16)
B14: * | C14: Những điều cốt yếu theo Học Năng : | AP14: =IF('Nhập liệu'!C17="","",'Nhập liệu'!C17)
E15: Thiên Nguyên khí : | F15: =Setup!V20 -> Càn | G15: =IF(Setup!R25<>"","Có"&Setup!R25&".","") -> Có, ở quẻ chính tiên thiên. | AP15: =IF('Nhập liệu'!C18="","",'Nhập liệu'!C18)
E16: Địa Nguyên khí : | F16: =Setup!V21 -> Ly | G16: =IF(Setup!R26<>"","Có"&Setup!R26&".","") -> Có, ở quẻ chính hậu thiên. | AP16: =IF('Nhập liệu'!C19="","",'Nhập liệu'!C19)
E17: Hóa Công : | F17: =Setup!V8 -> Khảm | G17: =IF(Setup!R27<>"","Có"&Setup!R27&".","") -> Có, ở quẻ hỗ hậu thiên. | AP17: =IF('Nhập liệu'!C20="","",'Nhập liệu'!C20)
E18: Yểm trợ : | F18: ="H."&Setup!AA40&Setup!AC40 -> H.5 dg | G18: =Setup!AA42 -> Có, hào 2 âm. | AP18: =IF('Nhập liệu'!C21="","",'Nhập liệu'!C21)
E19: ="TSD hợp "&Setup!A38&" :" -> TSD hợp mùa Xuân : | F19: =Setup!C38&"-"&Setup!D38 -> 25-35 | G19: =Setup!C39 | AP19: =IF('Nhập liệu'!C22="","",'Nhập liệu'!C22)
E20: ="TSÂ hợp "&Setup!A38&" :" -> TSÂ hợp mùa Xuân : | F20: =Setup!E38&"-"&Setup!F38 -> 30-34 | G20: =Setup!E39 | AP20: =IF('Nhập liệu'!C23="","",'Nhập liệu'!C23)
E21: Nạp giáp : | F21: =IF(G21<>"",Setup!R5,"") -> N.Ngọ | G21: =IF(Setup!U28<>"","Có"&Setup!U28&".","") -> Có, ở quẻ tiên thiên. | AP21: =IF('Nhập liệu'!C24="","",'Nhập liệu'!C24)
E22: Được tháng sinh : | F22: =IF(G22="","","Tháng "&Setup!B13) | G22: =IF(Setup!B13=Setup!W28,"Có, ở quẻ tiên thiên.",IF(Setup!B13=Setup!X28,"Có, ở quẻ hậu thiên.","")) | AP22: =IF('Nhập liệu'!C25="","",'Nhập liệu'!C25)
AP23: =IF('Nhập liệu'!C26="","",'Nhập liệu'!C26)
B24: * | C24: Cách quý hiển : | F24: =IF(Setup!E65<>"",Setup!B65,IF(Setup!E66<>"",Setup!B66,"")) | G24: =IF(Setup!E65<>"",Setup!E65,IF(Setup!E66<>"",Setup!E66,"")) | AP24: =IF('Nhập liệu'!C27="","",'Nhập liệu'!C27)
F25: =IF(AND(Setup!E65<>"",Setup!E66<>""),Setup!B66,"") | G25: =IF(AND(Setup!E65<>"",Setup!E66<>""),Setup!E66,"") | AP25: =IF('Nhập liệu'!C28="","",'Nhập liệu'!C28)
B26: * | C26: 10 thể cách của Hà Lạc : | AP26: =IF('Nhập liệu'!C29="","",'Nhập liệu'!C29)
C27: 1. | D27: Tên quẻ | F27: =Setup!I27 -> Bĩ | G27: =HLOOKUP(M10,'384Hào'!C3:BN74,2,0) -> Bĩ là tắc (Bế tắc, mắc kẹt). Được quẻ, 3 hào trên là đạo quân tử thì tốt, 3 hào dưới là đạo tiểu nhân thì xấu. | AP27: =IF('Nhập liệu'!C30="","",'Nhập liệu'!C30)
C28: 2. | D28: Hào vị NĐ | F28: ="Hào "&Setup!AA40 -> Hào 5 | G28: =VLOOKUP(Setup!AA40,Setup!Z43:AA48,2,0) -> Lập được nhiều công trạng. | AP28: =IF('Nhập liệu'!C31="","",'Nhập liệu'!C31)
C29: 3. | D29: Lời hào | G29: =HLOOKUP(M10,'384Hào'!C3:BN74,62-(VLOOKUP(1,Setup!AK4:AO15,5,0)-1)*11,0)&" "&HLOOKUP(M10,'384Hào'!C3:BN74,63-(VLOOKUP(1,Setup!AK4:AO15,5,0)-1)*11,0) -> Thôi hết bĩ, đại nhân tốt. Nhưng lo mất lo mất (phải giữ vững như) ràng buộc vào ngùm rễ dâu. Ý HÀO: Làm sáng tỏ con người của Hòa bình, để biết cái thuật giữ nghiệp lớn. | AP29: =IF('Nhập liệu'!C32="","",'Nhập liệu'!C32)
C30: 4. | D30: Được mùa | F30: =IF(G30="","","Tháng "&Setup!B13) | G30: =IF(Setup!B13=Setup!W28,"Có, ở quẻ tiên thiên.",IF(Setup!B13=Setup!X28,"Có, ở quẻ hậu thiên.","")) | AP30: =IF('Nhập liệu'!C33="","",'Nhập liệu'!C33)
C31: 5. | D31: Yểm trợ | F31: ="Hào "&Setup!AA40&Setup!AC40 -> Hào 5 dg | G31: =Setup!AA42 -> Có, hào 2 âm. | AP31: =IF('Nhập liệu'!C34="","",'Nhập liệu'!C34)
C32: 6. | D32: Thuận mùa | F32: ="TSD: "&Setup!C38&"-"&Setup!D38 -> TSD: 25-35 | G32: =Setup!C39 | AP32: =IF('Nhập liệu'!C35="","",'Nhập liệu'!C35)
D33: ="("&Setup!A38&")" -> (mùa Xuân) | F33: ="TSÂ: "&Setup!E38&"-"&Setup!F38 -> TSÂ: 30-34 | G33: =Setup!E39 | AP33: =IF('Nhập liệu'!C36="","",'Nhập liệu'!C36)
C34: 7. | D34: Được thể | F34: (Đang cập nhật) | G34: Tự đánh giá | AP34: =IF('Nhập liệu'!C37="","",'Nhập liệu'!C37)
C35: 8. | D35: Đáng vị | F35: =Setup!B92&" "&Setup!C92 -> Tháng dg | G35: =IF(Setup!C92=Setup!C93,"Có, vì "&Setup!B93&" NĐ "&Setup!C93&".","") -> Có, vì hào NĐ dg. | AP35: =IF('Nhập liệu'!C38="","",'Nhập liệu'!C38)
C36: 9. | D36: Hợp lý | F36: ="Tuổi "&Setup!C87 -> Tuổi Nhâm | G36: =IF(OR(Setup!C88<>"",Setup!C89<>""),"Có"&Setup!C88&Setup!C89&".","") -> Có, quẻ Càn ở tiên thiên. | AP36: =IF('Nhập liệu'!C39="","",'Nhập liệu'!C39)
C37: 10. | D37: Theo-Ghét | F37: =IF(OR(Setup!C77<>"",Setup!C84<>""),Setup!B77,IF(OR(Setup!C78<>"",Setup!C85<>""),Setup!B78,"")) | G37: =IF(Setup!C77<>"",Setup!B68&Setup!C77,IF(Setup!C84<>"",Setup!B80&Setup!C84,IF(AND(Setup!C77="",Setup!C84="",Setup!C78<>""),Setup!B68&Setup!C78,IF(AND(Setup!C77="",Setup!C84="",Setup!C85<>""),Setup!B80&Setup!C85,"")))) | AP37: =IF('Nhập liệu'!C40="","",'Nhập liệu'!C40)
F38: =IF(AND(G37<>"",OR(Setup!C77<>"",Setup!C84<>""),OR(Setup!C78<>"",Setup!C85<>"")),Setup!B78,"") | G38: =IF(AND(F38<>"",Setup!C78<>""),Setup!B68&Setup!C78,IF(AND(F38<>"",Setup!C85<>""),Setup!B80&Setup!C85,"")) | AP38: =IF('Nhập liệu'!C41="","",'Nhập liệu'!C41)
C39: (Chi tiết ý nghĩa các thể cách có trong sách "Bát tự Hà Lạc" của Học Năng) | AP39: =IF('Nhập liệu'!C42="","",'Nhập liệu'!C42)
C40: by: Lê Trung Tú | AP40: =IF('Nhập liệu'!C43="","",'Nhập liệu'!C43)
...

Sheet Đại Vận
S1: ="12 Đại vận - "&'Thể cách'!D3 -> 12 Đại vận - Lá số
A2: TIỀN VẬN: | E2: ="Từ "&VLOOKUP(1,Setup!AK4:AO15,2,0)&" tuổi đến "&VLOOKUP(6,Setup!AK4:AO15,4,0)&" tuổi" -> Từ 1 tuổi đến 45 tuổi | K2: ="Từ năm "&Setup!B15&" đến năm "&(Setup!B15-1+VLOOKUP(6,Setup!AK4:AO15,4,0)) -> Từ năm 2002 đến năm 2046
G3: =HLOOKUP(C13,'384Hào'!C3:BN74,2,0) -> Bĩ là tắc (Bế tắc, mắc kẹt). Được quẻ, 3 hào trên là đạo quân tử thì tốt, 3 hào dưới là đạo tiểu nhân thì xấu.
C4: =IF(AND(Setup!B26>=Setup!B15-1+VLOOKUP(1,Setup!AK4:AO15,2,0),Setup!B26<=Setup!B15-1+VLOOKUP(1,Setup!AK4:AO15,4,0)),"Đương vận","") | L4: =HLOOKUP(C13,'384Hào'!C3:BN74,3,0) -> Có lộc mà cũng không màng lộc, | N4: =HLOOKUP(C13,'384Hào'!C3:BN74,5,0) -> Chí người quân tử bền sao,
C5: =Setup!B15&"-"&(Setup!B15-1+VLOOKUP(1,Setup!AK4:AO15,4,0)) -> 2002-2010 | L5: =HLOOKUP(C13,'384Hào'!C3:BN74,4,0) -> Vị tuy cao chẳng lấy làm cao, | N5: =HLOOKUP(C13,'384Hào'!C3:BN74,6,0) -> Tiến lên đĩnh đạc anh hào thanh danh.
C6: =VLOOKUP(1,Setup!AK4:AO15,2,0)&"-"&VLOOKUP(1,Setup!AK4:AO15,4,0)&" Tuổi" -> 1-9 Tuổi | G6: =HLOOKUP(C13,'384Hào'!C3:BN74,62-(VLOOKUP(1,Setup!AK4:AO15,5,0)-1)*11,0) -> Thôi hết bĩ, đại nhân tốt. Nhưng lo mất lo mất (phải giữ vững như) ràng buộc vào ngùm rễ dâu.
B7: =IF(VLOOKUP(1,Setup!AK4:AO15,5,0)=6,"*","") | C7: =HLOOKUP(C13,'64Quẻ'!B5:DX11,2,0) -> ——— | D7: =IF(C13="","",HLOOKUP(C13&1,'64Quẻ'!B5:DY11,2,0)) -> N.Tuất | G7: =HLOOKUP(C13,'384Hào'!C3:BN74,63-(VLOOKUP(1,Setup!AK4:AO15,5,0)-1)*11,0) -> Ý HÀO: Làm sáng tỏ con người của Hòa bình, để biết cái thuật giữ nghiệp lớn.
B8: =IF(VLOOKUP(1,Setup!AK4:AO15,5,0)=5,"*","") -> * | C8: =HLOOKUP(C13,'64Quẻ'!B5:DX11,3,0) -> ——— | D8: =IF(C13="","",HLOOKUP(C13&1,'64Quẻ'!B5:DY11,3,0)) -> N.Thân | H8: =HLOOKUP(C13,'384Hào'!C3:BN74,64-(VLOOKUP(1,Setup!AK4:AO15,5,0)-1)*11,0) -> MHC: Có đức lớn, công bằng, cẩn thận, xét nét, không bỏ cơ hội, phú quý bền được.
B9: =IF(VLOOKUP(1,Setup!AK4:AO15,5,0)=4,"*","") | C9: =HLOOKUP(C13,'64Quẻ'!B5:DX11,4,0) -> ——— | D9: =IF(C13="","",HLOOKUP(C13&1,'64Quẻ'!B5:DY11,4,0)) -> N.Ngọ | H9: =HLOOKUP(C13,'384Hào'!C3:BN74,65-(VLOOKUP(1,Setup!AK4:AO15,5,0)-1)*11,0) -> MKH: Có tài đức, không gặp thời, bình sinh an vui, chẳng vinh, chẳng nhục.
B10: =IF(VLOOKUP(1,Setup!AK4:AO15,5,0)=3,"*","") | C10: =HLOOKUP(C13,'64Quẻ'!B5:DX11,5,0) -> — — | D10: =IF(C13="","",HLOOKUP(C13&1,'64Quẻ'!B5:DY11,5,0)) -> Ấ.Mão | I10: =HLOOKUP(C13,'384Hào'!C3:BN74,66-(VLOOKUP(1,Setup!AK4:AO15,5,0)-1)*11,0) -> QC: Ngồi chính vị.
B11: =IF(VLOOKUP(1,Setup!AK4:AO15,5,0)=2,"*","") | C11: =HLOOKUP(C13,'64Quẻ'!B5:DX11,6,0) -> — — | D11: =IF(C13="","",HLOOKUP(C13&1,'64Quẻ'!B5:DY11,6,0)) -> Ấ.Tỵ | I11: =HLOOKUP(C13,'384Hào'!C3:BN74,67-(VLOOKUP(1,Setup!AK4:AO15,5,0)-1)*11,0) -> GS: Họa đi phúc sắp lại, kẻ thù lui dần. Lo hóa mừng, mất thành được.
B12: =IF(VLOOKUP(1,Setup!AK4:AO15,5,0)=1,"*","") | C12: =HLOOKUP(C13,'64Quẻ'!B5:DX11,7,0) -> — — | D12: =IF(C13="","",HLOOKUP(C13&1,'64Quẻ'!B5:DY11,7,0)) -> Ấ.Mùi | I12: =HLOOKUP(C13,'384Hào'!C3:BN74,68-(VLOOKUP(1,Setup!AK4:AO15,5,0)-1)*11,0) -> NT: Họa đi phúc sắp lại, kẻ thù lùi dần. Ruộng vườn thâu hoạch. Lo hóa mừng, mất thành được. Số xấu tổn vong hình khắc.
C13: ='Thể cách'!M10 -> Bĩ | L13: =HLOOKUP(C13,'384Hào'!C3:BN74,69-(VLOOKUP(1,Setup!AK4:AO15,5,0)-1)*11,0) -> Thời đại thịnh, sắp tới nơi | N13: =HLOOKUP(C13,'384Hào'!C3:BN74,71-(VLOOKUP(1,Setup!AK4:AO15,5,0)-1)*11,0)
C14: =IF(C13="","",HLOOKUP(C13,'64Quẻ'!B5:DX25,21,0)) -> 7 | L14: =HLOOKUP(C13,'384Hào'!C3:BN74,70-(VLOOKUP(1,Setup!AK4:AO15,5,0)-1)*11,0) -> Nhưng đừng hờ hững, lỡ rồi xảy nguy. | N14: =HLOOKUP(C13,'384Hào'!C3:BN74,72-(VLOOKUP(1,Setup!AK4:AO15,5,0)-1)*11,0)
G15: =HLOOKUP(C25,'384Hào'!C3:BN74,2,0) -> Bĩ là tắc (Bế tắc, mắc kẹt). Được quẻ, 3 hào trên là đạo quân tử thì tốt, 3 hào dưới là đạo tiểu nhân thì xấu.
C16: =IF(AND(Setup!B26>=Setup!B15-1+VLOOKUP(2,Setup!AK4:AO15,2,0),Setup!B26<=Setup!B15-1+VLOOKUP(2,Setup!AK4:AO15,4,0)),"Đương vận","") | L16: =HLOOKUP(C25,'384Hào'!C3:BN74,3,0) -> Có lộc mà cũng không màng lộc, | N16: =HLOOKUP(C25,'384Hào'!C3:BN74,5,0) -> Chí người quân tử bền sao,
C17: =(Setup!B15-1+VLOOKUP(2,Setup!AK4:AO15,2,0))&"-"&Setup!B15-1+VLOOKUP(2,Setup!AK4:AO15,4,0) -> 2011-2019 | L17: =HLOOKUP(C25,'384Hào'!C3:BN74,4,0) -> Vị tuy cao chẳng lấy làm cao, | N17: =HLOOKUP(C25,'384Hào'!C3:BN74,6,0) -> Tiến lên đĩnh đạc anh hào thanh danh.
C18: =VLOOKUP(2,Setup!AK4:AO15,2,0)&"-"&VLOOKUP(2,Setup!AK4:AO15,4,0)&" Tuổi" -> 10-18 Tuổi | G18: =HLOOKUP(C25,'384Hào'!C3:BN74,62-(VLOOKUP(2,Setup!AK4:AO15,5,0)-1)*11,0) -> Đánh đổ được bĩ, trước bĩ sau mừng.
B19: =IF(VLOOKUP(2,Setup!AK4:AO15,5,0)=6,"*","") -> * | C19: =HLOOKUP(C25,'64Quẻ'!B5:DX11,2,0) -> ——— | D19: =IF(C25="","",HLOOKUP(C25&1,'64Quẻ'!B5:DY11,2,0)) -> N.Tuất | G19: =HLOOKUP(C25,'384Hào'!C3:BN74,63-(VLOOKUP(2,Setup!AK4:AO15,5,0)-1)*11,0) -> Ý HÀO: Bĩ đổ, hưởng phúc.
B20: =IF(VLOOKUP(2,Setup!AK4:AO15,5,0)=5,"*","") | C20: =HLOOKUP(C25,'64Quẻ'!B5:DX11,3,0) -> ——— | D20: =IF(C25="","",HLOOKUP(C25&1,'64Quẻ'!B5:DY11,3,0)) -> N.Thân | H20: =HLOOKUP(C25,'384Hào'!C3:BN74,64-(VLOOKUP(2,Setup!AK4:AO15,5,0)-1)*11,0) -> MHC: Chí lớn cương quyết, sắp đặt hơn người, trước gian truân, sau nhàn lạc.
B21: =IF(VLOOKUP(2,Setup!AK4:AO15,5,0)=4,"*","") | C21: =HLOOKUP(C25,'64Quẻ'!B5:DX11,4,0) -> ——— | D21: =IF(C25="","",HLOOKUP(C25&1,'64Quẻ'!B5:DY11,4,0)) -> N.Ngọ | H21: =HLOOKUP(C25,'384Hào'!C3:BN74,65-(VLOOKUP(2,Setup!AK4:AO15,5,0)-1)*11,0) -> MKH: Danh lợi khó thành, cốt nhục hình thương, tăng ni tốt.
B22: =IF(VLOOKUP(2,Setup!AK4:AO15,5,0)=3,"*","") | C22: =HLOOKUP(C25,'64Quẻ'!B5:DX11,5,0) -> — — | D22: =IF(C25="","",HLOOKUP(C25&1,'64Quẻ'!B5:DY11,5,0)) -> Ấ.Mão | I22: =HLOOKUP(C25,'384Hào'!C3:BN74,66-(VLOOKUP(2,Setup!AK4:AO15,5,0)-1)*11,0) -> QC: Mất chức thì được phục hồi. Chờ việc thì được bổ.
B23: =IF(VLOOKUP(2,Setup!AK4:AO15,5,0)=2,"*","") | C23: =HLOOKUP(C25,'64Quẻ'!B5:DX11,6,0) -> — — | D23: =IF(C25="","",HLOOKUP(C25&1,'64Quẻ'!B5:DY11,6,0)) -> Ấ.Tỵ | I23: =HLOOKUP(C25,'384Hào'!C3:BN74,67-(VLOOKUP(2,Setup!AK4:AO15,5,0)-1)*11,0) -> GS: Bị đình trệ thì phục hoạt, khốn lâu ngày được cởi mở.
B24: =IF(VLOOKUP(2,Setup!AK4:AO15,5,0)=1,"*","") | C24: =HLOOKUP(C25,'64Quẻ'!B5:DX11,7,0) -> — — | D24: =IF(C25="","",HLOOKUP(C25&1,'64Quẻ'!B5:DY11,7,0)) -> Ấ.Mùi | I24: =HLOOKUP(C25,'384Hào'!C3:BN74,68-(VLOOKUP(2,Setup!AK4:AO15,5,0)-1)*11,0) -> NT: Kiện tụng lâu được giải. Số xấu có biến cố, kém thọ.
C25: ='Thể cách'!M10 -> Bĩ | L25: =HLOOKUP(C25,'384Hào'!C3:BN74,69-(VLOOKUP(2,Setup!AK4:AO15,5,0)-1)*11,0) -> Bĩ qua liền Thái đến, | N25: =HLOOKUP(C25,'384Hào'!C3:BN74,71-(VLOOKUP(2,Setup!AK4:AO15,5,0)-1)*11,0) -> Mộc biên người ấy gặp (?!)
C26: =IF(C13="","",HLOOKUP(C13,'64Quẻ'!B5:DX25,21,0)) -> 7 | L26: =HLOOKUP(C25,'384Hào'!C3:BN74,70-(VLOOKUP(2,Setup!AK4:AO15,5,0)-1)*11,0) -> Kiển xong vận lại thông. | N26: =HLOOKUP(C25,'384Hào'!C3:BN74,72-(VLOOKUP(2,Setup!AK4:AO15,5,0)-1)*11,0) -> Trăm việc tốt vô cùng.
G27: =HLOOKUP(C37,'384Hào'!C3:BN74,2,0) -> Bĩ là tắc (Bế tắc, mắc kẹt). Được quẻ, 3 hào trên là đạo quân tử thì tốt, 3 hào dưới là đạo tiểu nhân thì xấu.
C28: =IF(AND(Setup!B26>=Setup!B15-1+VLOOKUP(3,Setup!AK4:AO15,2,0),Setup!B26<=Setup!B15-1+VLOOKUP(3,Setup!AK4:AO15,4,0)),"Đương vận","") | L28: =HLOOKUP(C37,'384Hào'!C3:BN74,3,0) -> Có lộc mà cũng không màng lộc, | N28: =HLOOKUP(C37,'384Hào'!C3:BN74,5,0) -> Chí người quân tử bền sao,
C29: =(Setup!B15-1+VLOOKUP(3,Setup!AK4:AO15,2,0))&"-"&Setup!B15-1+VLOOKUP(3,Setup!AK4:AO15,4,0) -> 2020-2025 | L29: =HLOOKUP(C37,'384Hào'!C3:BN74,4,0) -> Vị tuy cao chẳng lấy làm cao, | N29: =HLOOKUP(C37,'384Hào'!C3:BN74,6,0) -> Tiến lên đĩnh đạc anh hào thanh danh.
C30: =VLOOKUP(3,Setup!AK4:AO15,2,0)&"-"&VLOOKUP(3,Setup!AK4:AO15,4,0)&" Tuổi" -> 19-24 Tuổi | G30: =HLOOKUP(C37,'384Hào'!C3:BN74,62-(VLOOKUP(3,Setup!AK4:AO15,5,0)-1)*11,0) -> Nhổ rể cỏ mao, lấy cả cụm (cả 3 hào âm), giữ chính thì tốt và hanh thông.
B31: =IF(VLOOKUP(3,Setup!AK4:AO15,5,0)=6,"*","") | C31: =HLOOKUP(C37,'64Quẻ'!B5:DX11,2,0) -> ——— | D31: =IF(C37="","",HLOOKUP(C37&1,'64Quẻ'!B5:DY11,2,0)) -> N.Tuất | G31: =HLOOKUP(C37,'384Hào'!C3:BN74,63-(VLOOKUP(3,Setup!AK4:AO15,5,0)-1)*11,0) -> Ý HÀO: Trở lại với điều chính thì tốt.
B32: =IF(VLOOKUP(3,Setup!AK4:AO15,5,0)=5,"*","") | C32: =HLOOKUP(C37,'64Quẻ'!B5:DX11,3,0) -> ——— | D32: =IF(C37="","",HLOOKUP(C37&1,'64Quẻ'!B5:DY11,3,0)) -> N.Thân | H32: =HLOOKUP(C37,'384Hào'!C3:BN74,64-(VLOOKUP(3,Setup!AK4:AO15,5,0)-1)*11,0) -> MHC: Người có danh dự, dời tổ đi lập nghiệp bên ngoài, bỏ gần theo xa, chí để vào việc công, đừng tư kỷ thì hưởng phúc.
B33: =IF(VLOOKUP(3,Setup!AK4:AO15,5,0)=4,"*","") | C33: =HLOOKUP(C37,'64Quẻ'!B5:DX11,4,0) -> ——— | D33: =IF(C37="","",HLOOKUP(C37&1,'64Quẻ'!B5:DY11,4,0)) -> N.Ngọ | H33: =HLOOKUP(C37,'384Hào'!C3:BN74,65-(VLOOKUP(3,Setup!AK4:AO15,5,0)-1)*11,0) -> MKH: Liệu thời hãy tiến, tri cơ nên lui, thời gian nan. Khó hành chí, giữ lấy thân gia cho khỏi tai nguy.
B34: =IF(VLOOKUP(3,Setup!AK4:AO15,5,0)=3,"*","") | C34: =HLOOKUP(C37,'64Quẻ'!B5:DX11,5,0) -> — — | D34: =IF(C37="","",HLOOKUP(C37&1,'64Quẻ'!B5:DY11,5,0)) -> Ấ.Mão | I34: =HLOOKUP(C37,'384Hào'!C3:BN74,66-(VLOOKUP(3,Setup!AK4:AO15,5,0)-1)*11,0) -> QC: Chờ bổ nhiệm, đương tại chức bị dèm pha.
B35: =IF(VLOOKUP(3,Setup!AK4:AO15,5,0)=2,"*","") | C35: =HLOOKUP(C37,'64Quẻ'!B5:DX11,6,0) -> — — | D35: =IF(C37="","",HLOOKUP(C37&1,'64Quẻ'!B5:DY11,6,0)) -> Ấ.Tỵ | I35: =HLOOKUP(C37,'384Hào'!C3:BN74,67-(VLOOKUP(3,Setup!AK4:AO15,5,0)-1)*11,0) -> GS: Khó gặp cơ hội.
B36: =IF(VLOOKUP(3,Setup!AK4:AO15,5,0)=1,"*","") -> * | C36: =HLOOKUP(C37,'64Quẻ'!B5:DX11,7,0) -> — — | D36: =IF(C37="","",HLOOKUP(C37&1,'64Quẻ'!B5:DY11,7,0)) -> Ấ.Mùi | I36: =HLOOKUP(C37,'384Hào'!C3:BN74,68-(VLOOKUP(3,Setup!AK4:AO15,5,0)-1)*11,0) -> NT: Nên thủ cựu, phòng có việc liên quan lôi thôi.
C37: ='Thể cách'!M10 -> Bĩ | L37: =HLOOKUP(C37,'384Hào'!C3:BN74,69-(VLOOKUP(3,Setup!AK4:AO15,5,0)-1)*11,0) -> Vận bĩ thủ phận là hay, | N37: =HLOOKUP(C37,'384Hào'!C3:BN74,71-(VLOOKUP(3,Setup!AK4:AO15,5,0)-1)*11,0)
C38: =IF(C13="","",HLOOKUP(C13,'64Quẻ'!B5:DX25,21,0)) -> 7 | L38: =HLOOKUP(C37,'384Hào'!C3:BN74,70-(VLOOKUP(3,Setup!AK4:AO15,5,0)-1)*11,0) -> Đừng khi vọng động tai bay vạ liền. | N38: =HLOOKUP(C37,'384Hào'!C3:BN74,72-(VLOOKUP(3,Setup!AK4:AO15,5,0)-1)*11,0)
G39: =HLOOKUP(C49,'384Hào'!C3:BN74,2,0) -> Bĩ là tắc (Bế tắc, mắc kẹt). Được quẻ, 3 hào trên là đạo quân tử thì tốt, 3 hào dưới là đạo tiểu nhân thì xấu.
C40: =IF(AND(Setup!B26>=Setup!B15-1+VLOOKUP(4,Setup!AK4:AO15,2,0),Setup!B26<=Setup!B15-1+VLOOKUP(4,Setup!AK4:AO15,4,0)),"Đương vận","") -> Đương vận | L40: =HLOOKUP(C49,'384Hào'!C3:BN74,3,0) -> Có lộc mà cũng không màng lộc, | N40: =HLOOKUP(C49,'384Hào'!C3:BN74,5,0) -> Chí người quân tử bền sao,
...

Sheet Vận Năm
A1: ="Vận Năm - "&'Thể cách'!D3 -> Vận Năm - Lá số | N1: Trong đại vận: | O1: =VLOOKUP(Setup!AK3,Setup!AK4:AO15,2,0)&" tuổi - "&VLOOKUP(Setup!AK3,Setup!AK4:AO15,4,0)&" tuổi" -> 31 tuổi - 36 tuổi | P1: =(Setup!B15-1+VLOOKUP(Setup!AK3,Setup!AK4:AO15,2,0))&" - "&Setup!B15-1+VLOOKUP(Setup!AK3,Setup!AK4:AO15,4,0) -> 2032 - 2037
G2: =HLOOKUP(C12,'384Hào'!C3:BN74,2,0) -> Độn là Thoái (lùi về, ở ẩn).
C3: =IF(B4=Setup!B26,"Năm nay","") | L3: =HLOOKUP(C12,'384Hào'!C3:BN74,3,0) -> Đừng kêu: Vận kiển mãi trời ! | N3: =HLOOKUP(C12,'384Hào'!C3:BN74,5,0)
B4: =Setup!AT30 -> 2032 | L4: =HLOOKUP(C12,'384Hào'!C3:BN74,4,0) -> Chờ năm Sửu Ngọ đường đời thênh thang. | N4: =HLOOKUP(C12,'384Hào'!C3:BN74,6,0)
C5: =INDEX(Setup!D11:D20,MOD(B4,10)+1)&" "&INDEX(Setup!E4:E15,MOD(B4,12)+1) -> Nhâm Tý | G5: =HLOOKUP(C12,'384Hào'!C3:BN74,62-(Setup!AQ12-1)*11,0) -> Ẩn tránh mà vẫn bị ràng buộc (bởi 2 hào âm dưới), nên có bệnh và nguy đấy, chỉ nuôi thiếp tôi là tốt.
B6: =IF(Setup!AR3="*","*",IF(Setup!AR3="","")) | C6: =IF((C12)="","",HLOOKUP(C12,'64Quẻ'!B5:DX11,2,0)) -> ——— | D6: =IF(C12="","",HLOOKUP(C12&1,'64Quẻ'!B5:DY11,2,0)) -> N.Tuất | G6: =HLOOKUP(C12,'384Hào'!C3:BN74,63-(Setup!AQ12-1)*11,0) -> Ý HÀO: Đáng ẩn trách mà còn hệ lụy không tránh được.
B7: =IF(Setup!AR4="*","*",IF(Setup!AR4="","")) | C7: =IF((C12)="","",HLOOKUP(C12,'64Quẻ'!B5:DX11,3,0)) -> ——— | D7: =IF(C12="","",HLOOKUP(C12&1,'64Quẻ'!B5:DY11,3,0)) -> N.Thân | H7: =HLOOKUP(C12,'384Hào'!C3:BN74,64-(Setup!AQ12-1)*11,0) -> MHC: Minh triết giữ được thân, dũng thoái thoát được nạn. Hoặc có hiền thê giúp sức, hoặc có nô bộc hết lòng.
B8: =IF(Setup!AR5="*","*",IF(Setup!AR5="","")) | C8: =IF((C12)="","",HLOOKUP(C12,'64Quẻ'!B5:DX11,4,0)) -> ——— | D8: =IF(C12="","",HLOOKUP(C12&1,'64Quẻ'!B5:DY11,4,0)) -> N.Ngọ | H8: =HLOOKUP(C12,'384Hào'!C3:BN74,65-(Setup!AQ12-1)*11,0) -> MKH: Chỉ ăn nhậu, tham tài tham sắc, tật lệ liên miên hoặc bị nô tỳ liên lụy.
B9: =IF(Setup!AR6="*","*",IF(Setup!AR6="","")) -> * | C9: =IF((C12)="","",HLOOKUP(C12,'64Quẻ'!B5:DX11,5,0)) -> ——— | D9: =IF(C12="","",HLOOKUP(C12&1,'64Quẻ'!B5:DY11,5,0)) -> B.Thân | F9: =Setup!AR13 -> TNK | I9: =HLOOKUP(C12,'384Hào'!C3:BN74,66-(Setup!AQ12-1)*11,0) -> QC: Có cái lo về chức phận.
B10: =IF(Setup!AR7="*","*",IF(Setup!AR7="","")) | C10: =IF((C12)="","",HLOOKUP(C12,'64Quẻ'!B5:DX11,6,0)) -> — — | D10: =IF(C12="","",HLOOKUP(C12&1,'64Quẻ'!B5:DY11,6,0)) -> B.Ngọ | F10: =Setup!AR14 | I10: =HLOOKUP(C12,'384Hào'!C3:BN74,67-(Setup!AQ12-1)*11,0) -> GS: Không thành đại sự.
B11: =IF(Setup!AR8="*","*",IF(Setup!AR8="","")) | C11: =IF((C12)="","",HLOOKUP(C12,'64Quẻ'!B5:DX11,7,0)) -> — — | D11: =IF(C12="","",HLOOKUP(C12&1,'64Quẻ'!B5:DY11,7,0)) -> B.Thìn | F11: =Setup!AR15 | I11: =HLOOKUP(C12,'384Hào'!C3:BN74,68-(Setup!AQ12-1)*11,0) -> NT: Nhiều tật ách. Số tốt thì được vợ đắc lực, nhà thêm người.
C12: =IF('Đại Vận'!C13="","",HLOOKUP(Setup!AP15,'64Quẻ'!B4:DX5,2,0)) -> Độn | L12: =HLOOKUP(C12,'384Hào'!C3:BN74,69-(Setup!AQ12-1)*11,0) -> Phòng tật bệnh, gan việc thường | N12: =HLOOKUP(C12,'384Hào'!C3:BN74,71-(Setup!AQ12-1)*11,0)
C13: =IF(C12="","",HLOOKUP(C12,'64Quẻ'!B5:DX25,21,0)) -> 6 | L13: =HLOOKUP(C12,'384Hào'!C3:BN74,70-(Setup!AQ12-1)*11,0) -> Mưu to chớ ngả, rẽ đường đưa tin. | N13: =HLOOKUP(C12,'384Hào'!C3:BN74,72-(Setup!AQ12-1)*11,0)
G14: =HLOOKUP(C24,'384Hào'!C3:BN74,2,0) -> Tiệm là Tiến (tiến dần như chim bay lên cao dần).
C15: =IF(B16=Setup!B26,"Năm nay","") | L15: =HLOOKUP(C24,'384Hào'!C3:BN74,3,0) -> Ôm cần đợi cá bên sông, | N15: =HLOOKUP(C24,'384Hào'!C3:BN74,5,0)
B16: =B4+1 -> 2033 | L16: =HLOOKUP(C24,'384Hào'!C3:BN74,4,0) -> Đợi lâu được cá xúm đông đớp mồi. | N16: =HLOOKUP(C24,'384Hào'!C3:BN74,6,0)
C17: =INDEX(Setup!D11:D20,MOD(B16,10)+1)&" "&INDEX(Setup!E4:E15,MOD(B16,12)+1) -> Quý Sửu | G17: =HLOOKUP(C24,'384Hào'!C3:BN74,62-(Setup!AQ19-1)*11,0) -> Chim hồng tiến dần lên trên cây, hoặc được cái cành bằng, không lỗi gì.
B18: =IF(AND(Setup!AT32=5,B7="*"),"*",IF(AND(Setup!AT32=8,B9="*"),"*","")) | C18: =IF((C24)="","",HLOOKUP(C24,'64Quẻ'!B5:DX11,2,0)) -> ——— | D18: =IF(C24="","",HLOOKUP(C24&1,'64Quẻ'!B5:DY11,2,0)) -> T.Mão | G18: =HLOOKUP(C24,'384Hào'!C3:BN74,63-(Setup!AQ19-1)*11,0) -> Ý HÀO: Gặp bạo mà được yên lành.
B19: =IF(AND(Setup!AT32=5,B8="*"),"*",IF(AND(Setup!AT32=8,B10="*"),"*","")) | C19: =IF((C24)="","",HLOOKUP(C24,'64Quẻ'!B5:DX11,3,0)) -> ——— | D19: =IF(C24="","",HLOOKUP(C24&1,'64Quẻ'!B5:DY11,3,0)) -> T.Tỵ | H19: =HLOOKUP(C24,'384Hào'!C3:BN74,64-(Setup!AQ19-1)*11,0) -> MHC: Có đức có vị nhưng khiêm nhường thì suốt đời an vui.
B20: =IF(AND(Setup!AT32=5,B9="*"),"*",IF(AND(Setup!AT32=8,B11="*"),"*","")) -> * | C20: =IF((C24)="","",HLOOKUP(C24,'64Quẻ'!B5:DX11,4,0)) -> — — | D20: =IF(C24="","",HLOOKUP(C24&1,'64Quẻ'!B5:DY11,4,0)) -> T.Mùi | H20: =HLOOKUP(C24,'384Hào'!C3:BN74,65-(Setup!AQ19-1)*11,0) -> MKH: Sinh kế khó khăn, phải kiệm ước, muộn mới đủ dùng.
B21: =IF(AND(Setup!AT32=5,B10="*"),"*",IF(AND(Setup!AT32=8,B6="*"),"*","")) | C21: =IF((C24)="","",HLOOKUP(C24,'64Quẻ'!B5:DX11,5,0)) -> ——— | D21: =IF(C24="","",HLOOKUP(C24&1,'64Quẻ'!B5:DY11,5,0)) -> B.Thân | F21: =Setup!AR20 | I21: =HLOOKUP(C24,'384Hào'!C3:BN74,66-(Setup!AQ19-1)*11,0) -> QC: Gặp cường bạo không chế phục nổi, đổi việc, vô định.
B22: =IF(AND(Setup!AT32=5,B11="*"),"*",IF(AND(Setup!AT32=8,B7="*"),"*","")) | C22: =IF((C24)="","",HLOOKUP(C24,'64Quẻ'!B5:DX11,6,0)) -> — — | D22: =IF(C24="","",HLOOKUP(C24&1,'64Quẻ'!B5:DY11,6,0)) -> B.Ngọ | F22: =Setup!AR21 -> ĐNK | I22: =HLOOKUP(C24,'384Hào'!C3:BN74,67-(Setup!AQ19-1)*11,0) -> GS: Đỗ khoa mùa thu.
B23: =IF(AND(Setup!AT32=5,B6="*"),"*",IF(AND(Setup!AT32=8,B8="*"),"*","")) | C23: =IF((C24)="","",HLOOKUP(C24,'64Quẻ'!B5:DX11,7,0)) -> — — | D23: =IF(C24="","",HLOOKUP(C24&1,'64Quẻ'!B5:DY11,7,0)) -> B.Thìn | F23: =Setup!AR22 -> HC | I23: =HLOOKUP(C24,'384Hào'!C3:BN74,68-(Setup!AQ19-1)*11,0) -> NT: Lợi việc tu tạo, nhà yên ổn.
C24: =IF('Đại Vận'!C13="","",HLOOKUP(Setup!AP22,'64Quẻ'!B4:DX5,2,0)) -> Tiệm | L24: =HLOOKUP(C24,'384Hào'!C3:BN74,69-(Setup!AQ19-1)*11,0) -> Non cao xứ đẹp vui cùng, | N24: =HLOOKUP(C24,'384Hào'!C3:BN74,71-(Setup!AQ19-1)*11,0)
C25: =IF(C24="","",HLOOKUP(C24,'64Quẻ'!B5:DX25,21,0)) -> 1 | L25: =HLOOKUP(C24,'384Hào'!C3:BN74,70-(Setup!AQ19-1)*11,0) -> Mận đào điểm nhụy, cúc mừng lợi danh. | N25: =HLOOKUP(C24,'384Hào'!C3:BN74,72-(Setup!AQ19-1)*11,0)
G26: =HLOOKUP(C36,'384Hào'!C3:BN74,2,0) -> Cấn là Chỉ (ngăn bước, ngừng lại, trở ngại trùng trùng).
C27: =IF(B28=Setup!B26,"Năm nay","") | L27: =HLOOKUP(C36,'384Hào'!C3:BN74,3,0) -> Tiến hành nay Bắc với mai Đông, | N27: =HLOOKUP(C36,'384Hào'!C3:BN74,5,0) -> Lui tới chầu cao, sau có lối
B28: =B4+2 -> 2034 | L28: =HLOOKUP(C36,'384Hào'!C3:BN74,4,0) -> Cầu lộc cầu tài việc cũng thông. | N28: =HLOOKUP(C36,'384Hào'!C3:BN74,6,0) -> Nhưng là nên thủy lại nên chung.
C29: =INDEX(Setup!D11:D20,MOD(B28,10)+1)&" "&INDEX(Setup!E4:E15,MOD(B28,12)+1) -> Giáp Dần | G29: =HLOOKUP(C36,'384Hào'!C3:BN74,62-(Setup!AQ26-1)*11,0) -> Biết ngừng ở mép mình, nói năng có thứ tự, khỏi ăn năn gì.
B30: =IF(AND(Setup!AT32=5,B19="*"),"*",IF(AND(Setup!AT32=8,B21="*"),"*","")) | C30: =IF((C36)="","",HLOOKUP(C36,'64Quẻ'!B5:DX11,2,0)) -> ——— | D30: =IF(C36="","",HLOOKUP(C36&1,'64Quẻ'!B5:DY11,2,0)) -> B.Dần | G30: =HLOOKUP(C36,'384Hào'!C3:BN74,63-(Setup!AQ26-1)*11,0) -> Ý HÀO: Dè dặt lời nói; nên đỡ lỗi.
B31: =IF(AND(Setup!AT32=5,B20="*"),"*",IF(AND(Setup!AT32=8,B22="*"),"*","")) -> * | C31: =IF((C36)="","",HLOOKUP(C36,'64Quẻ'!B5:DX11,3,0)) -> — — | D31: =IF(C36="","",HLOOKUP(C36&1,'64Quẻ'!B5:DY11,3,0)) -> B.Tý | H31: =HLOOKUP(C36,'384Hào'!C3:BN74,64-(Setup!AQ26-1)*11,0) -> MHC: Có đức, có lập ngôn, lớn thì làm ngoại giao, nhỏ thì làm giáo sư.
B32: =IF(AND(Setup!AT32=5,B21="*"),"*",IF(AND(Setup!AT32=8,B23="*"),"*","")) | C32: =IF((C36)="","",HLOOKUP(C36,'64Quẻ'!B5:DX11,4,0)) -> — — | D32: =IF(C36="","",HLOOKUP(C36&1,'64Quẻ'!B5:DY11,4,0)) -> B.Tuất | H32: =HLOOKUP(C36,'384Hào'!C3:BN74,65-(Setup!AQ26-1)*11,0) -> MKH: Thì cũng ngâm nga như Đào Tiềm, luận bàn kim cổ, được bằng hữu phụ hội, sinh kế bình thường.
B33: =IF(AND(Setup!AT32=5,B22="*"),"*",IF(AND(Setup!AT32=8,B18="*"),"*","")) | C33: =IF((C36)="","",HLOOKUP(C36,'64Quẻ'!B5:DX11,5,0)) -> ——— | D33: =IF(C36="","",HLOOKUP(C36&1,'64Quẻ'!B5:DY11,5,0)) -> B.Thân | F33: =Setup!AR27 | I33: =HLOOKUP(C36,'384Hào'!C3:BN74,66-(Setup!AQ26-1)*11,0) -> QC: Hiển đạt thì ở vị cao cấp Trung Ương, chưa hiển đạt thì cũng giữ chức ngôn luận.
B34: =IF(AND(Setup!AT32=5,B23="*"),"*",IF(AND(Setup!AT32=8,B19="*"),"*","")) | C34: =IF((C36)="","",HLOOKUP(C36,'64Quẻ'!B5:DX11,6,0)) -> — — | D34: =IF(C36="","",HLOOKUP(C36&1,'64Quẻ'!B5:DY11,6,0)) -> B.Ngọ | F34: =Setup!AR28 | I34: =HLOOKUP(C36,'384Hào'!C3:BN74,67-(Setup!AQ26-1)*11,0) -> GS: Nhờ một lời nói trúng đại nhân mà khoa danh thành tựu.
B35: =IF(AND(Setup!AT32=5,B18="*"),"*",IF(AND(Setup!AT32=8,B20="*"),"*","")) | C35: =IF((C36)="","",HLOOKUP(C36,'64Quẻ'!B5:DX11,7,0)) -> — — | D35: =IF(C36="","",HLOOKUP(C36&1,'64Quẻ'!B5:DY11,7,0)) -> B.Thìn | F35: =Setup!AR29 -> HC | I35: =HLOOKUP(C36,'384Hào'!C3:BN74,68-(Setup!AQ26-1)*11,0) -> NT: Hợp nhân tình, mưu được toại ý. Số xấu thì vạ miệng. Già trẻ khó về sinh kế.
C36: =IF('Đại Vận'!C13="","",HLOOKUP(Setup!AP29,'64Quẻ'!B4:DX5,2,0)) -> Cấn | L36: =HLOOKUP(C36,'384Hào'!C3:BN74,69-(Setup!AQ26-1)*11,0) -> Lời ngay cùng lẽ phải, | N36: =HLOOKUP(C36,'384Hào'!C3:BN74,71-(Setup!AQ26-1)*11,0) -> Đừng hiềm danh lợi muộn,
C37: =IF(C36="","",HLOOKUP(C36,'64Quẻ'!B5:DX25,21,0)) -> 4 | L37: =HLOOKUP(C36,'384Hào'!C3:BN74,70-(Setup!AQ26-1)*11,0) -> Nên không hối hận gì. | N37: =HLOOKUP(C36,'384Hào'!C3:BN74,72-(Setup!AQ26-1)*11,0) -> Xuân sang phúc lộc kỳ.
G38: =HLOOKUP(C48,'384Hào'!C3:BN74,2,0) -> Khiêm là thoái (thoái nhượng, lùi, nhường bước, nhũn nhặn).
C39: =IF(B40=Setup!B26,"Năm nay","") | L39: =HLOOKUP(C48,'384Hào'!C3:BN74,3,0) -> Lẽ đời lo ngại nhiễu phiền, | N39: =HLOOKUP(C48,'384Hào'!C3:BN74,5,0)
B40: =B4+3 -> 2035 | L40: =HLOOKUP(C48,'384Hào'!C3:BN74,4,0) -> Tấm gương chiếu rọi nhãn tiền hư không. | N40: =HLOOKUP(C48,'384Hào'!C3:BN74,6,0)
...

Sheet 384Hào
C2: 1 | D2: 2 | E2: 3 | F2: 4 | G2: 5 | H2: 6 | I2: 7 | J2: 8 | K2: 9 | L2: 10 | M2: 11 | N2: 12 | O2: 13 | P2: 14 | Q2: 15 | R2: 16 | S2: 17 | T2: 18 | U2: 19 | V2: 20 | W2: 21 | X2: 22 | Y2: 23 | Z2: 24 | AA2: 25 | AB2: 26 | AC2: 27 | AD2: 28 | AE2: 29 | AF2: 30 | AG2: 31 | AH2: 32 | AI2: 33 | AJ2: 34 | AK2: 35 | AL2: 36 | AM2: 37 | AN2: 38 | AO2: 39 | AP2: 40 | AQ2: 41 | AR2: 42 | AS2: 43 | AT2: 44 | AU2: 45 | AV2: 46 | AW2: 47 | AX2: 48 | AY2: 49 | AZ2: 50 | BA2: 51 | BB2: 52 | BC2: 53 | BD2: 54 | BE2: 55 | BF2: 56 | BG2: 57 | BH2: 58 | BI2: 59 | BJ2: 60 | BK2: 61 | BL2: 62 | BM2: 63 | BN2: 64
C3: Càn | D3: Khôn | E3: Truân | F3: Mông | G3: Nhu | H3: Tụng | I3: Sư | J3: Tỷ | K3: T.Súc | L3: Lý | M3: Thái | N3: Bĩ | O3: Đ.Nhân | P3: Đ.Hữu | Q3: Khiêm | R3: Dự | S3: Tùy | T3: Cổ | U3: Lâm | V3: Quan | W3: P.Hạp | X3: Bí | Y3: Bác | Z3: Phục | AA3: V.Vọng | AB3: Đ.Súc | AC3: Di | AD3: Đ.Quá | AE3: Khảm | AF3: Ly | AG3: Hàm | AH3: Hằng | AI3: Độn | AJ3: Đ.Tráng | AK3: Tấn | AL3: M.Di | AM3: G.Nhân | AN3: Khuể | AO3: Kiển | AP3: Giải | AQ3: Tổn | AR3: Ích | AS3: Quải | AT3: Cấu | AU3: Tụy | AV3: Thăng | AW3: Khốn | AX3: Tỉnh | AY3: Cách | AZ3: Đỉnh | BA3: Chấn | BB3: Cấn | BC3: Tiệm | BD3: Q.Muội | BE3: Phong | BF3: Lữ | BG3: Tốn | BH3: Đoài | BI3: Hoán | BJ3: Tiết | BK3: T.Phu | BL3: T.Quá | BM3: K.Tế | BN3: V.Tế
C4: Kiền là Kiện (khỏe mạnh). Lại sanh từ tháng 2 đến trước tháng 8 là được mùa sanh, hưởng phúc đức. Dù ở hào vị kém cũng vẫn tốt. Nếu không được tuổi Nạp giáp và không được mùa sinh, thì dù ngồi hào vị tốt cũng vẫn là người vất vả long đong và kiêu trá nữa. | D4: Khôn là thuận (Thuận lợi, hiền từ). Nếu sanh tháng 10 thì chắc chắn làm chức vị lớn (ngày xưa là bậc đại thần) danh cao đức hậu. Nếu sinh không đúng mùa, lại ngồi hào vị kém, thì cũng làm chủ nhân ông điền sản, hưởng phúc lộc thọ. Thầy tu thì phước dày. Nữ mạng thì hiếu hòa, chồng sang con quý. | E4: Truân là nan (khó khăn, nhưng rồi có cơ hội). Lại sanh vào tháng 6 là cách công danh, phú quý. Sinh từ tháng 2 đến tháng 8 cũng được hưởng phúc dày. Những tháng khác thì kém. | F4: Mông là Muội (còn ngu tối cần được hướng dẫn). | G4: Nhu là thuận (mềm dẻo, đợi chờ thời cơ). Lại sanh tháng 8 là cách phú quý. Cần được số âm dương, Nguyên đường, Quẻ Hào hợp cách là đúng số tốt. | H4: Tụng là Luận (bàn cãi, kiện tụng). | I4: Sư là chúng (đám đông, quân đội) gian nan rồi thành công. (Chữ SƯ ngày xưa gợi ý: Sư-Phó, Sư-Bảo, Sư-Tướng, Thiên Sư v.v… Ngày nay có luật sư, giáo sư v.v...) | J4: Tỷ là Hòa (sánh vai, gần gũi, gặp dịp thuận tiện để phát triển). | K4: Tiểu Súc là Tắc (sự bế tắc nhỏ, chờ sắp giải quyết). | L4: Lý là lễ (trật tự, pháp độ thiên nhiên). | M4: Thái là Thông (thời vận hanh thông, rất tốt). Phàm số được quẻ này mà hợp cách cục là cực tốt. Có triệu chứng xuất tướng nhập tướng. Lại sanh tháng 1 là cách công danh phú quý, nếu sinh không đúng thời mà phúc nhỏ, thì chỉ nên thủ phận an thường. | N4: Bĩ là tắc (Bế tắc, mắc kẹt). Được quẻ, 3 hào trên là đạo quân tử thì tốt, 3 hào dưới là đạo tiểu nhân thì xấu. | O4: Đồng Nhân là Thân (tìm bạn đồng tâm đồng lực). | P4: Đại Hữu là Khoan (rộng lớn). | Q4: Khiêm là thoái (thoái nhượng, lùi, nhường bước, nhũn nhặn). | R4: Dự là Duyệt (hòa vui). Lại sanh tháng 5 là cách công danh phú quý. Sấm nổ tháng 3, tháng 8 cũng vang lừng, đại phú quý. Những tháng khác, phúc nhỏ. | S4: Tùy là Thuận (theo hoàn cảnh). Lại sanh tháng 7 là cách công danh phú quý, sinh từ tháng 2 đến tháng 8 cũng phúc dày. Sinh từ tháng 9 đến tháng 1 thì phúc kém. | T4: Cổ là Sự, Hoại (lắm việc, hư hoại). Phàm được quẻ này phần nhiều bắt đầu phải gian nan, hoặc mê muội, sau mới làm thành, được thừa hưởng tổ nghiệp. Nhưng đối với cha mẹ, gia đình, không được thuận thảo. | U4: Lâm là Đại (lớn tức người trên đến với người dưới). | V4: Quan là quan sát (xem xét kiểm thảo). | W4: Phệ Hạp là Khiết hợp (cắn ngậm lại, ngục hình). Lại sanh tháng 2, tháng 8 là cách công danh phú quý | X4: Bí là sức (trang sức, làm cảnh đẹp thêm). | Y4: Bác là Lạc (rơi rụng, tan mất). Được quẻ này phần nhiều là người làm lớn hay là quý nhân nhưng không tránh khỏi cô lập hình khắc. Lại sanh tháng 9 là cách công danh phú quý. Sinh những tháng khác thì không khỏi anh em bất hòa, bôn ba vất vả. | Z4: Phục là Phản (trở lại). | AA4: Vô Vọng là Vô dục vọng (phóng nhậm tự nhiên). | AB4: Đại súc là Tụ (tích trữ sức lớn để chờ thời). | AC4: Di là Dưỡng (nuôi). Lại sanh tháng tháng 2 đến tháng 8 là cách công danh phú quý. | AD4: Đại Quá là Họa (hư hao, gian nan, lớn đi quá mức). | AE4: Khảm là Hãm (hiểm, mắc kẹt, linh lạc, gian nan). | AF4: Ly là Lệ (sáng đẹp, văn minh). | AG4: Hàm là Cảm (giao cảm, cảm thông, cảm động). | AH4: Hằng là Cửu (lâu, thường luôn, đương nhiên cứ thế). Lại sanh tháng 1 là cách công danh phú quý. Sinh từ tháng 9 đến tháng 12 thì phúc kém. | AI4: Độn là Thoái (lùi về, ở ẩn). | AJ4: Đại Tráng là Chí (tức Ý chí là mạnh). Lại sanh tháng 2 là cách công danh phú quý. Xuân hạ thì được phúc dày. Thu đông phúc mỏng, tháng 7, 8 hãy còn được mùa. | AK4: Tấn là Tiến (tiến bước, thời vận đến). | AL4: Minh Di là Thương (có ánh sáng nhưng bị tổn thương). | AM4: Gia Nhân là Đồng (cùng với người nhà hòa thuận vui vẻ). | AN4: Khuê là Vi, Bội (trái ngược nhau, khác nhau). | AO4: Kiển là Nan (gian nan, vất vả). | AP4: Giải là Tán (Tan biến cởi mở hoạn nạn, uất ức…). Lại sanh tháng 12 là cách công danh phú quý. Tháng 2 tháng 8 sấm mưa đúng mùa thì phúc cũng dày. Từ tháng 9 đến tháng 1 (trừ tháng 12) thì phúc mỏng. | AQ4: Tổn là Ích (mình chịu tổn một ích để làm lợi ích cho người. Gần như hỷ xả. Tổn mà không mất hẳn, vì có cơ được hồi lại, gần như đầu tư). | AR4: Ích là Tổn (Tổn trên mà ích dưới mới thật là Ích). Lại sanh tháng 7 là cách công danh phú quý. Sinh từ tháng 2 đến tháng 8 thì phúc dày. Các tháng khác phúc nhỏ. | AS4: Quải là Quyết (quyết đấu, quyết tâm, quyết nghị, quyết đoán...). Lại sanh tháng 3 là cách công danh phú quý, Kiền Đoài đều là Kim, sinh mùa thu cũng được mùa. | AT4: Cấu là Ngộ (ngẫu nhiên gặp gỡ). | AU4: Tụy là Tụ (tụ họp đông đảo: thi thố, vui buồn phức tạp). | AV4: Thăng là Tiến (từ thấp tiến dần lên cao). | AW4: Khốn là Nguy (nguy nan khốn khổ, nên kiên nhẫn). | AX4: Tỉnh là Tĩnh (an tĩnh đợi thời vận như đợi mạch nước giếng thơi). | AY4: Cách là Cải (thay đổi mạnh mẽ, thay cũ đổi mới). | AZ4: Đỉnh là Định (An định, đặt yên như đỉnh đứng 3 chân vững vàng). | BA4: Chấn là Động (chấn động như sấm nổ vang, phấn phát lên, thanh thế mạnh lớn). | BB4: Cấn là Chỉ (ngăn bước, ngừng lại, trở ngại trùng trùng). | BC4: Tiệm là Tiến (tiến dần như chim bay lên cao dần). | BD4: Quy Muội là Đại, là bất chính thức (không căng trì tế nhị, xử sự đại đi cho xong việc, sau sẽ làm cứ hối, cần phải kiểm thảo). | BE4: Phong là Phong mãn, Phong phú, là Đại (lớn, đầy, thịnh nên e rằng đến cực rồi sẽ suy). | BF4: Lữ là Khách (khách lữ hành đi xa, không yên trí, lúc nào cũng phải thận trọng). | BG4: Tốn là Thuận (thuận nhi nhập, thuận theo để đi vào một công việc gì, có mềm dẻo mới thành công). Lại sanh tháng 4 là cách công danh phú quý, sanh mùa Xuân, mùa Hạ cũng được phúc dày. | BH4: Đoài là Duyệt (hỷ duyệt, vui lòng, vừa ý, song hỷ...). | BI4: Hoán là Tán (tiêu tan, không tụ một chỗ). | BJ4: Tiết là Chỉ (hữu hạn nhi chỉ, đến một thời gian nào thì ngừng. Có chừng mực, có tiết độ, tiết tháo, tiết chế). | BK4: Trung Phu là Tín (chí thành, hòa hoãn, thong thả). | BL4: Tiểu Quá (cái nhỏ đi quá một chút, bất hòa). | BM4: Ký Tế là Dĩ thành (đã thành rồi, danh lợi đủ cả, chỉ phòng khi thịnh hóa suy). | BN4: Vị Tế là Thất (mất thăng bằng, chưa thành đạt, nhưng chớ bi quan, có hy vọng).
C5: Vận Kiền công nghiệp ai bì, | D5: Cá đầy nước, Giai nhân ngọc đẹp, | E5: Ra tay gỡ mối Kinh Luân, | F5: Tiến thoái ý chưa quyết, | G5: Vỗ chèo, bơi miết trên sông | H5: Bước chân vào chỗ chông gai, | I5: Sức đám đông, rõ bầy ra | J5: Rừng cây, xuân tới nơi | K5: Trường sơn muốn vượt về thăm, | L5: Nơi này dù chửa an tâm, | M5: Tuần hoàn bĩ thái luật trời, | N5: Có lộc mà cũng không màng lộc, | O5: Bĩ lâu nay, sạch nạn rồi | P5: Bụi đời đắm đuối bao phen, | Q5: Lẽ đời lo ngại nhiễu phiền, | R5: Tiếng sấm vang lừng bao biến hóa, | S5: Âm dương xuất xử phải tùy, | T5: Việc dù có đẹp nữa chăng, | U5: Cẩn thường điều độ không sai, | V5: Yên thân lợi xứ hành, | W5: Ngục tù phép tắc có minh, | X5: Không cầu, lộc tự trời cho | Y5: Bền dưới nhà ở mới yên, | Z5: Một đời danh lợi thực hư, | AA5: Thân này bằng cấp cũng không, | AB5: Mái chèo vượt sóng muôn trùng, | AC5: Hương đan quế, áng công danh | AD5: Tâm thừa, lực thiếu ngán không, | AE5: Hiểm nghèo Khảm muốn thông, | AF5: Ngán lâu, nay thấy sáng ngời | AG5: Tự nhiên thông cảm sâu xa, | AH5: Ngồi yên quân tử chớ lo, | AI5: Đừng kêu: Vận kiển mãi trời ! | AJ5: Giữ chí, còn mưu chỉ họa tai, | AK5: Thưởng công, nước dựng dân an | AL5: Người rình trong đất tổn thương, | AM5: Rồi đây gia đạo thịnh, | AN5: Lẻ hồng bay tít dặm ngoài, | AO5: Phòng Đông-Bắc, lợi Tây-Nam | AP5: Cửa rồng vốn là khách, | AQ5: Cá mừng mưa ao cạn, | AR5: Ích tổn tại hào ba, | AS5: Phong lưu bố thí rất nên, | AT5: Gái bé đương đông chẳng đủ lo, | AU5: Âm dương hội họp mà chưa hẹn, | AV5: Tiến bước Đông Nam tốt, | AW5: Thiên hình sau chẳng đổi, | AX5: Muốn xem an lạc nơi nào, | AY5: Việc đời vốn vất vả, | AZ5: Ba chân Đỉnh đứng vững vàng, | BA5: Quế nguyệt hương đưa dặm, | BB5: Tiến hành nay Bắc với mai Đông, | BC5: Ôm cần đợi cá bên sông, | BD5: Về đi mé nước thơm lừng, | BE5: Ước hẹn rồi như mộng, | BF5: Chưa về, chưa thấy dê hầu (Mùi Thân) | BG5: Trên non không thấy mắt xanh, | BH5: Được dùng chính ở phương Tây, | BI5: Mộng vào đường thẳm thiên thai, | BJ5: Đường đi hiểm trở thì thôi, | BL5: Việc trong năm Tý Ngọ, (Tý Ngọ niên trung sự) | BM5: Trị an nên trị loạn, | BN5: Cưỡi rồng phòng thất lạc,
C6: Rồng bay chín cõi Nam Nhi thỏa lòng. | D6: Hoa đầy đường. Ngựa thuận dong cương. | E6: Trước nguy sau vững, gió xuân ôn hòa. | F6: Lòng ngờ việc chưa thành. | G6: Trước sau chưa rõ vận mòng dở hay. | H6: Thấy ai chảnh hoảnh, gượng cười cho êm. | I6: Vô tâm mà được bao la nắm quyền. | J6: Cảnh vật mới thơm tươi. | K6: Con thuyền trăng chiếu, âm thầm quê ta. | L6: Mấy hồi kinh hãi tri âm giúp liền. | M6: Mừng khi sinh dục được thời phong quang. | N6: Vị tuy cao chẳng lấy làm cao, | O6: Sông to buồm nhẹ, mây trời xanh xanh. | P6: Gặp dê hội mới, mới lên dần dần. | Q6: Tấm gương chiếu rọi nhãn tiền hư không. | R6: Núi rừng xanh tốt, vững non sông. | S6: Tâm can tùng bách coi gì tuyết sương. | T6: Cũng phòng ba lượt bị băng hoại liền. | U6: Tấm thân an tĩnh, niềm vui thái hòa. | V6: Quan sát khắp dân tình. | W6: Thì đời mới có tiến trình phong quang. | X6: Xưa buồn, nay gặp trâu bò lại vui. | Y6: Đề phòng bất trắc lo phiền xảy ra. | Z6: Quay đầu chỉ thấy thân cô mộng tàn. | AA6: Anh hùng đồ điếu lập công phi thường. | AB6: Lưỡi câu sẵn có, doanh bồng đường đây. | AC6: Người đi muôn dặm, cảnh tình vẫn thơm. | AD6: Gió xuân, chống gậy, khuây lòng câu ca. | AE6: Giữ nước, phải tương dung. | AF6: Hoàn cầu hội mới mở thời văn minh. | AG6: Giờ nên lấy vợ coi là hoàng kim. | AH6: Tiền đồ chẳng ngại trời cho chu tuyền. | AI6: Chờ năm Sửu Ngọ đường đời thênh thang. | AJ6: Nước trời gặp được tốt hòa đôi. | AK6: Tin xa tốt đẹp, trăm ngàn lộc vinh. | AL6: Tuổi dương phòng bệnh khó lường hư hao. | AM6: Âm đức nhờ tổ tông, | AN6: Tiệc vui sinh ý ngược đời, xa nhau. | AO6: Trong mây có một khác phàm giai nhân. | AP6: Sang năm cưỡi cá kình. | AQ6: Rồng mây gặp gỡ thời. | AR6: Thấy lành phải đổi ra. | AS6: Đại nhân cùng gặp hết liền gian nguy. | AT6: Chiếc thuyền lui tới sóng dềnh to. | AU6: Thuyền đóng bên sông định cứu nguy. | AV6: Trời xanh, ngày lại dài. | AW6: Kim mộc khó bề yên. | AX6: Trước tiên nghe tiếng hô hào giúp nhau. | AY6: Tuy lo chẳng ngại gì. | AZ6: Chim bằng cất cánh Quảng hàn đâu xa. | BA6: Lên mây, nỏ mất tiêu. | BB6: Cầu lộc cầu tài việc cũng thông. | BC6: Đợi lâu được cá xúm đông đớp mồi. | BD6: Mận đào một đóa đợi chừng gió xuân. | BE6: Vô duyên bị kẹt liền. | BF6: Quý nhân đội Đẩu trên đầu sáng choang. | BG6: Bên sông gặp gỡ tâm tình thương nhau. | BH6: Cùng nhau giảng tập vui vầy anh em. | BI6: Lên non chuyện ấy cùng ai hẹn ngày. | BJ6: Giữ mình tiết độ, an vui dễ dàng. | BL6: Lập gốc trước chờ heo. (Phùng chư tiên lập căn) | BM6: Vận thái dễ truân tai. | BN6: Đuôi ướt cứ loanh quanh.
D7: Đất dày chở vật, | F7: Muốn nên danh và lợi, | G7: Chiếc roi cầm sẵn trên tay, | I7: Kể ra lãnh đạo rất phiền, | J7: Hoa nở mừng nơi trú, | M7: Tiền trình giữ bước vững vàng, | N7: Chí người quân tử bền sao, | P7: Lo sao chân thực mọi phần, | T7: Vinh hoa đừng cậy uy quyền, | V7: Quẫn bách thu đông khoảng, | AE7: Sẻ quạ đương bày trận, | AH7: Phong thư đến, tự nhật biên | AJ7: Lập thân chính đại không hư hiểm, | AM7: Ân trạch trời cho giáng, | AP7: Doanh châu không chịu ở, | AQ7: Còn gì mà chẳng đẹp, | AR7: Lộc rừng xuân mới đến, | AT7: Từ đầu ngựa chạy không mang lỗi, | AU7: Hoa rụng trước sân thành quả mới, | AV7: Mệnh tươi, tai họa sạch | AW7: Chuột bọ khinh không hại, | AY7: Đổi thay cũ mới phải THÌ, Lợi tìm về phía Đông Nam, | BA7: Cánh bằng chưa dễ kịp, | BB7: Lui tới chầu cao, sau có lối | BE7: Nếu cầu hanh thái vận, | BG7: Hàn vi sau ắt sang giàu, | BH7: Gió xuân đào lý ấm êm, | BI7: Sắc xuân hương lạ gió bay, | BJ7: Niềm vui cũng phải có chừng, | BK7: Tín thành báo hỷ thường ngay, | BL7: Lộc tự trên trời xuống, (Lộc tòng thiên thượng chi) | BM7: Lợi nhỏ tìm Tây Bắc, | BN7: Nếu được cao nhân giúp,
D8: Tiến bước huy hoàng. | F8: Đợi buổi nhất dương sinh. (Quẻ phục tháng 11) | G8: Chuyến đi mừng sẽ thu này vẻ vang. | I8: Nhưng điều lợi lộc tùy duyên có nhiều. | J8: Hồng tâm điểm trúng rồi. | M8: Trên đường muôn dặm gió dương thuận buồm. | N8: Tiến lên đĩnh đạc anh hào thanh danh. | P8: Có người Mộc Khẩu ân nhân đấy mà. (Yêu cầu chân dữ thực. Mộc khẩu thị ân nhân). | T8: Sợ rằng đeo nhục khổ phiền thân tâm. | V8: Thấy hùm cũng chớ kinh. | AE8: Cùng trời chiếc nhạn tung. | AH8: Gần xa bốn biển đã truyền danh thơm. | AJ8: Tự thủ, trong rừng một quả khai. | AM8: Hai con được cưỡi rồng. | AP8: Đài điện rắp công khanh. | AQ8: Năm canh bóng nguyệt soi. | AR8: Cảm khái nếp vinh hoa. | AT8: Sợ lệnh truyền sau chửa khắp cho. | AU8: Sắp đi Tây Bắc việc còn nghi. | AV8: Danh lợi được hòa hai. | AW8: Tai nguy ngay thấy liền. | AY8: Sao cho hợp lý tùy nghi là làm. Còn phương Tây Bắc đừng nhằm mà nguy. | BA8: Nhàn tọa vẻ thanh kiêu. | BB8: Nhưng là nên thủy lại nên chung. | BE8: Phải đợi buổi Dần, Thìn. | BG8: Nhờ ơn tri ngộ, công đầu hiển vinh. | BH8: Hóa rồng nghìn dặm ngày thêm vẫy vùng. | BI8: Cành xưa hoa nở lần này đẹp hơn. | BJ8: Kiêu dâm vô độ sẵn sàng biến hung. | BK8: Hầu, Long (Thân, Thìn) mà đến, đường mây nhẹ nhàng. | BL8: Hai voi chật cửa theo (Nhị tượng mãn môn lan) | BM8: Hoa tân buổi sớm mai. | BN8: Còn gì sợ với khinh.
A9: 6 | B9: Lược nghĩa: | C9: Rồng lên cao quá, có sự hối hận. | D9: Rồng chiến ngoài nội, máu chảy đen vàng. (hào âm đến cùng cực nên xấu, Âm dương sát phạt nhau). | E9: Cưỡi ngựa dùng dằng, như (ư !) khóc ra máu chảy đầm đìa như (ư !) (thời cùng khổ). | F9: Phép đánh bật ngu tối đi, đừng nên làm cho trẻ (ức quá) mà thành giặc, không lợi. | G9: Vào nơi hang hiểm. Có ba người khách thong dong đi lại. Kính trọng họ, sau tốt. | H9: Hoặc tặng cho hắn đai lớn, trọn buổi mai, hắn lại bị tước lại ba lần. (hào 6 hay kiện, dù được khen tặng cũng chốc được chốc mất). | I9: Đại quân (nguyên thủ) có mệnh trời ra mở nước, nối nghiệp nhà, kẻ tiểu nhân chớ có dùng. | J9: Sánh vai chẳng có đầu, xấu. | K9: Đã mưa, đã ổn rồi (hào 4 âm đã được lòng cả 5 hào dương). Sự sùng đức (đối với phe âm) đã chở đầy; (nhưng ví như) người đàn bà cố chấp, có thể nguy đấy; Mặt trăng gần tới rằm (âm thịnh lắm) người Quân tử đừng vội tiến hành mà xấu. | L9: Xem lại lý lịch để xét điềm lành, thấy trọn vẹn, tốt nhất. | M9: Thành đổ xuống ụ đất, chớ dùng quân sự nữa, chỉ phát mệnh lệnh ở ấp mình thôi, giữ chính, nhưng cũng hối thẹn. | N9: Đánh đổ được bĩ, trước bĩ sau mừng. | O9: Cùng người ở khoảng đất ngoài thành, không hối hận. | P9: Tự trời giúp cho; tốt, không có gì là chẳng lợi. | Q9: Khiêm nhường có tiếng, dùng việc hành quân có lợi ích chinh phục được ấp nước mình thôi. | R9: Tối tăm mê vui, nhưng rồi có thay đổi, không lỗi gì. | S9: (Tùy gắn bó như) móc buộc lấy, lại theo mà dằng giữ lấy, vương dùng tế hưởng ở đất Tây Sơn (nghiệp lớn thành). | T9: Không thờ vương hầu, chỉ sùng cao chí của mình. | U9: Đầy đặn mà tới, tốt, không lỗi gì. | V9: Tự xem xét cách sống của mình, người Quân tử không lỗi. | W9: Đội cái cùm, đứt tai, xấu (nói người bị hình phạt). | X9: Trang sức trắng nguyên, không lỗi gì. | Y9: Quả lớn không ăn, người Quân tử được xe (dân chở) kẻ tiểu nhân sụp nhà. | Z9: Hôn mê ở thời phục là xấu: Có vạ ngoài lỗi trong, dùng hành quân sau thua to, đến nỗi quốc quân bị xấu, tới mười năm chẳng tiến lên được nữa. | AA9: Để tự nhiên, làm thì hại, không lỗi gì. | AB9: Sao mà đường trời hanh thông thế ! | AC9: Do mình mà có cái nuôi, nguy nhưng tốt, vượt sông lớn có lợi. | AD9: Lội xâu quá, ngập lút cả đỉnh đầu, xấu nhưng không lỗi gì. | AE9: Buộc (tay) dùng dây đàn, đặt (chân) vào bụi gai, ba năm chẳng được gì, xấu. | AF9: Vương dùng việc ra quân chinh phạt. Có điều tốt đẹp là bẻ gãy được tên đầu bọn, chẳng bắt tụi xấu xa theo đuôi, không lỗi gì. | AG9: Cảm đến mép, má, lưỡi (toàn bộ phận ăn nói). | AH9: Làm chấn động đạo hằng, xấu. | AI9: Ẩn tránh mà khoan thai, không có gì là không lợi. | AJ9: Con dê đực húc bờ giậu, không lùi được, không thỏa ý được, không lợi gì cả, chịu khó thời tốt. | AK9: Tiến lên đến chỗ sừng của mình (hào thượng) nhưng chỉ dùng việc trừng phạt ấp riêng của mình, dù nguy vẫn tốt, không lỗi gì, nhưng được chính cũng là xấu thẹn. | AL9: Chẳng sáng mà tối đen, mới thì lên tận trời, sau thì vào tận đất. | AM9: Có tin tưởng, thêm oai nghiêm nữa, sau hẳn tốt. | AN9: Cô đơn ở thời Khuê, thấy con heo đội bùn (bẩn lắm) một xe chở quỷ (xấu lắm), trước giương cung (định bắn) sau tháo cung ra; không phải giặc đâu, đó là người muốn kết hôn, thôi đi, gặp mưa (giải nồng) là tốt. (Tất cả trên là thái độ của hào 6 đối với hào 3, trước ngờ, sau hết ngờ, và hòa hợp). | AO9: Đi nữa thì vất vả, trở lại được việc lớn, tốt, lợi về việc gặp đại nhân (hào 5). | AP9: Ông tác dụng bắn con chim chuẩn ở trên ngọn tường cao, trúng được nó, không gì là chẳng lợi. | AQ9: Chẳng làm tổn ai nữa (Tổn đến cực rồi) mà làm ích cho người (cho hào 3), không lỗi gì, giữ chính nên tốt, ích lợi đấy tiến đi, sẽ được người quy phục mình, không cứ ở nhà riêng nào. | AR9: Chẳng làm ích thêm nữa (đến cùng rồi còn gì) hoặc đánh đuổi đi (thì có oán), lập tâm không theo đạo hằng thì xấu. | AS9: Không kêu khóc ai được (tiểu nhân hết thời rồi), kết cục là xấu. | AT9: Chỉ gặp cái sừng của mình (hào 6 cương mà ở trên cùng) xấu thẹn, không trách lỗi ai được (tự mình cô lập). | AU9: Than thở, khóc chảy nước mắt, nước mũi, mà không biết lỗi tại ai. | AV9: Cầu lên nữa là mờ ám (lên đến cùng rồi, chỉ còn có lợi ở chỗ giữ chinh không ngừng). | AW9: Bị khốn nơi dây sắn, nơi gập ghềnh, rằng hoạt động thì ăn năn, có ăn năn nhưng cứ tiến hành thì tốt (vì hết thời khốn rồi). | AX9: Giếng nước múc lên, chớ che đậy (cho mọi người cùng ăn) cứ thường thế mãi, thì tốt nhất. | AY9: Người Quân tử (lớp dân hiểu biết thực tình với cách mệnh) thì như con báo biến hóa, còn kẻ tiểu nhân (lớp dân trí nông cạn) thì cũng cách ngoài mặt (sẽ hóa dần dần); nhưng đến đây tiến hành nữa thời xấu (hào 6, giai đoạn cuối rồi), cứ giữ chính bền thời tốt. | AZ9: Cái đòn khiêng đỉnh bằng ngọc (chất cương mà hòa nhuận) điều tốt lớn lắm, không có gì là chẳng lợi. | BA9: Sấm mỏi mỏi (đến cùng rồi) nhìn kinh ngạc, tiến hành thời xấu, sấm chưa tới nơi hàng xóm, nên không lỗi gì, việc cưới xin có điều tiếng. | BB9: Dày dặn về cách ngăn ngừa, tốt. | BC9: Chim hồng tiến dần đến nơi đường mây, lông nó có thể dùng làm đồ hành ngơi (cờ quạt để đi rước), tốt. | BD9: Gái bưng giỏ mà không có thức gì chứa (để cúng lễ không xứng đáng làm vợ) trai học trò cắt tiết con dê mà không có máu (để cúng lễ, không xứng làm chồng). Không có gì ích lợi được nữa (hào 6 và hào 2 đều là âm không hợp đạo vợ chồng). | BE9: Lớn thay cái nóc, che lấp cả chỗ ở, nhìn vào ngỏ, vắng tanh không người, ba năm chẳng thấy mặt, xấu. | BF9: Như chim bị cháy tổ, lữ khách trước thì cười nói, sau phải kêu gào; mất trâu (hay bò) vì tính khinh dễ, nên mắc hung họa. | BG9: Tốn thuận như nép xuống dưới giường, mất cả tiền của và đồ phòng thân, ngoan cố càng xấu. | BH9: Kéo dài sự hòa vui (được nữa chăng ?). | BI9: Thời hoán, trừ khử được cái hại huyết đau, tống được điều sợ hãi đi, là không lỗi gì. | BJ9: Khổ sở về việc giữ tiết (vì thái quá) cứ cố giữ nữa thì xấu, biết hối hận thì khỏi xấu. | BK9: Tiếng chim bay lên trời (mà không thấy hình) cố chấp thì xấu, (hết thời tin rồi mà cứ tin thì hỏng). | BL9: Chẳng đúng đạo lý mà quá đấy, chim bay xa đấy, xấu, cho nên tai vạ. | BM9: Ngập cả đầu, nguy. | BN9: Tự tin (thong dong chờ thời) như khi uống rượu, không lỗi gì, nhưng nếu (để rượu) ướt cả đầu (đi quá trớn) thì tự tin là đánh mất lẽ phải rồi.
B10: Ý HÀO: | C10: Ý HÀO: Răn nên lưu ý khi đã bước lên tới chỗ cao vời, bấp bênh nguy hiểm của sự thịnh vượng. | D10: Ý HÀO: Âm cực, xảy ra tai họa. | E10: Ý HÀO: Tiến lên thì chẳng biết đi đâu, lo sợ vô cùng. | F10: Ý HÀO: Phải ngăn giặc (thói xấu) cho nó, thì mới có lợi. | G10: Ý HÀO: Đối với người tự dưng đến với mình mà càng kính trọng thì có thể thoát hiểm. | H10: Ý HÀO: Nên chấm dứt kiện đi, vì trước thắng, sau bại. | I10: Ý HÀO: Lập công danh đến tột mức, mà không lợi dụng vinh thăng. | J10: Ý HÀO: Kém đức thì sao cảm phục được thiên hạ. | K10: Ý HÀO: Tôn sùng đức mạnh của phe âm là hại đấy. | L10: Ý HÀO: Tận tâm với đạo lý, đạt phúc quả. | M10: Ý HÀO: Muốn cố giữ trị quyền sau khi Bĩ đã đến, rút cục chỉ thêm hổ thẹn. | N10: Ý HÀO: Bĩ đổ, hưởng phúc. | O10: Ý HÀO: Đứng riêng, tự thủ, cũng có điều sở đắc. | P10: Ý HÀO: Biết khéo xử ở thời Đại Hữu nên trời cũng giúp cho. | Q10: Ý HÀO: Khiêm nhường và dùng tài có giới hạn thôi. | R10: Ý HÀO: Vui thỏa thích nhưng biết cải biến thì không lỗi. | S10: Ý HÀO: Lấy lòng thành mà dùng đạo tùy, có thể thông cảm được với thần minh. | T10: Ý HÀO: Có đức mà không được dùng, giữ chí ở ẩn. | U10: Ý HÀO: Thân với người, rất đầy đặn. | V10: Ý HÀO: Trở lại bản thân để tự trị, làm tiêu biểu cho dân. | W10: Ý HÀO: Ác lớn, tội nặng. | X10: Ý HÀO: Trang sức đến cùng, trở về gốc cũ nên tránh được lầm lỗi. | Y10: Ý HÀO: Đi cùng đường, mà người Quân tử vẫn thế. | Z10: Ý HÀO: Sau cùng hôn mê không biết trở lại là xấu. | AA10: Ý HÀO: Tin chắc quá thì rồi hết cả tin. | AB10: Ý HÀO: Chứa càng được nhiều, thì lúc thi thố ra càng rộng lớn. | AC10: Ý HÀO: Có quyền có vị, làm việc lớn đất nước. | AD10: Ý HÀO: Tử nạn vì nước. | AE10: Ý HÀO: Vô tài mà ở chỗ cực hiểm tất nguy vong. | AF10: Ý HÀO: Việc chinh phạt đem lại sự chính đáng. | AG10: Ý HÀO: Nói cách cảm người. | AH10: Ý HÀO: Chỉ tạo động, lên không biết cố thủ, thế là không đúng đạo hằng. | AI10: Ý HÀO: Ẩn tránh mà thân khoan thai là hay. | AJ10: Ý HÀO: Hết thời tráng rồi mà còn cứ tráng, thì không lợi gì. | AK10: Ý HÀO: Vô đức, ngồi cao mà không miễn được sự trừng phạt ấp mình. | AL10: Ý HÀO: Vô đức nên không giữ được ngôi lớn. | AM10: Ý HÀO: Phải chỉnh việc nhà để đi tới kết quả thì mới tốt. | AN10: Ý HÀO: Đối với người ứng viện, trước ngờ sau hợp. | AO10: Ý HÀO: Cái nghĩa ở chỗ cứ theo vị lãnh đạo. | AP10: Ý HÀO: Giải tán được giặc bên ngoài. | AQ10: Ý HÀO: Gắng công chính đạo, làm ích lợi cho bên dưới. | AR10: Ý HÀO: Cần ích đến cùng, hoặc đến nổi phải đánh đuổi thì nhiều người oán. | AS10: Ý HÀO: Bè tiểu nhân đã hết, mà tai họa chưa lùi. | AT10: Ý HÀO: Cương không gặp ai hết. | AU10: Ý HÀO: Vô tài, vô vị mà tụ họp thiên hạ, chỉ thêm lo sợ. | AV10: Ý HÀO: Chỉ biết lên mà không biết ngừng. | AW10: Ý HÀO: Không có tài cứu khốn, nên phản tỉnh. | AX10: Ý HÀO: Đức trạch đã phổ biến, nên giữ gốc mãi. | AY10: Ý HÀO: Cách mệnh đã thành hình. Giữ chính đạo. | AZ10: Ý HÀO: Đức đẹp, công thành. | BA10: Ý HÀO: Vô tài nên chịu tai hung vậy. | BB10: Ý HÀO: Ngừng lại ở mức chí thiện. | BC10: Ý HÀO: Vượt ra ngoài sự thường tình. | BD10: Ý HÀO: Vô đức, vô ứng, ước trước mà không hẹn sau. | BE10: Ý HÀO: Sáng quá hóa tối nên xấu vậy. | BF10: Ý HÀO: Lữ khách ở nơi cao quá nên mắc họa. | BG10: Ý HÀO: Quá tốn thuận, nên xấu. | BH10: Ý HÀO: Chuyên việc làm vui người. | BI10: Ý HÀO: Có công cứu thời hoán, không hổ thẹn. | BJ10: Ý HÀO: Giữ tiết quá đáng cho nên xấu. | BK10: Ý HÀO: Không đáng tin mà cứ tin là có hại. | BL10: Ý HÀO: Đi quá rồi nên bị tai vạ. | BM10: Ý HÀO: Tài đủ tế thế, nhưng nguy. | BN10: Ý HÀO: Thuận mệnh trời để làm hết nhân sự.
